<?xml version="1.0" encoding="utf-8"?>
<robot name="L5_umi">
    <link name="base_link">
        <inertial>
            <origin xyz="-0.00013359 6.672E-05 0.031672" rpy="0 0 0" />
            <mass value="0.42272" />
            <inertia
                ixx="0.00060728"
                ixy="3.437e-7"
                ixz="9.790e-7"
                iyy="0.00060832"
                iyz="-1.696e-6"
                izz="1.917e-4" />
        </inertial>
        <visual>
            <origin xyz="0 0 0" rpy="0 0 0" />
            <geometry>
                <mesh filename="package://meshes/L5/base_link.STL" />
            </geometry>
            <material name="">
                <color rgba="0.89804 0.91765 0.92941 1" />
            </material>
        </visual>
        <collision>
            <origin xyz="0 0 0" rpy="0 0 0" />
            <geometry>
                <mesh filename="package://meshes/L5/base_link.STL" />
            </geometry>
        </collision>
    </link>
    <link name="link1">
        <inertial>
            <origin xyz="0.005056 -0.0078534 0.020887" rpy="0 0 0" />
            <mass value="0.09728" />
            <inertia ixx="0.00011" ixy="-0.00001" ixz="0.00001" iyy="0.00005" iyz="-0.00001"
                izz="0.00010" />
        </inertial>
        <visual>
            <origin xyz="0 0 0" rpy="0 0 0" />
            <geometry>
                <mesh filename="package://meshes/L5/link1.STL" />
            </geometry>
            <material name="">
                <color rgba="0.56471 0.56471 0.56471 1" />
            </material>
        </visual>
        <collision>
            <origin xyz="0 0 0" rpy="0 0 0" />
            <geometry>
                <mesh filename="package://meshes/L5/link1.STL" />
            </geometry>
        </collision>
    </link>
    <joint name="joint1" type="revolute">
        <origin xyz="0 0 0.0565" rpy="0 0 0" />
        <parent link="base_link" />
        <child link="link1" />
        <axis xyz="0 0 1" />
        <limit lower="-10" upper="10" effort="100" velocity="1000" />
    </joint>
    <link name="link2">
        <inertial>
            <origin xyz="-0.12983 -0.00073729 -1.2236E-05" rpy="0 0 0" />
            <mass value="1.1477" />
            <inertia ixx="0.00057063"
                ixy="0.00011251"
                ixz="0.00001979"
                iyy="0.03669927"
                iyz="1.203e-8"
                izz="0.03683489" />
        </inertial>
        <visual>
            <origin xyz="0 0 0" rpy="0 0 0" />
            <geometry>
                <mesh filename="package://meshes/L5/link2.STL" />
            </geometry>
            <material name="">
                <color rgba="0.69804 0.69804 0.69804 1" />
            </material>
        </visual>
        <collision>
            <origin xyz="0 0 0" rpy="0 0 0" />
            <geometry>
                <mesh filename="package://meshes/L5/link2.STL" />
            </geometry>
        </collision>
    </link>
    <joint name="joint2" type="revolute">
        <origin xyz="0.02 0 0.047" rpy="0 0 0" />
        <parent link="link1" />
        <child link="link2" />
        <axis xyz="0 1 0" />
        <limit lower="-10" upper="10" effort="100" velocity="1000" />
    </joint>
    <link name="link3">
        <inertial>
            <origin xyz="0.15404 5.5044E-07 -0.054689" rpy="0 0 0" />
            <mass value="0.66" />
            <inertia ixx="0.00178249"
                ixy="-0.00003986"
                ixz="0.00571"
                iyy="0.02486615"
                iyz="1.346e-5"
                izz="0.02329476" />
        </inertial>
        <visual>
            <origin xyz="0 0 0" rpy="0 0 0" />
            <geometry>
                <mesh filename="package://meshes/L5/link3.STL" />
            </geometry>
            <material name="">
                <color rgba="0.89804 0.91765 0.92941 1" />
            </material>
        </visual>
        <collision>
            <origin xyz="0 0 0" rpy="0 0 0" />
            <geometry>
                <mesh filename="package://meshes/L5/link3.STL" />
            </geometry>
        </collision>
    </link>
    <joint name="joint3" type="revolute">
        <origin xyz="-0.264 0 0" rpy="3.1416 0 0" />
        <parent link="link2" />
        <child link="link3" />
        <axis xyz="0 1 0" />
        <limit lower="-10" upper="10" effort="100" velocity="1000" />
    </joint>
    <link name="link4">
        <inertial>
            <origin xyz="0.040231 0.0039307 -0.035335" rpy="0 0 0" />
            <mass value="0.11714" />
            <inertia ixx="0.00017832"
                ixy="0.00001697"
                ixz="0.0000776"
                iyy="0.00021182"
                iyz="-0.00001779"
                izz="0.00011328" />
        </inertial>
        <visual>
            <origin xyz="0 0 0" rpy="0 0 0" />
            <geometry>
                <mesh filename="package://meshes/L5/link4.STL" />
            </geometry>
            <material name="">
                <color rgba="0.56471 0.56471 0.56471 1" />
            </material>
        </visual>
        <collision>
            <origin xyz="0 0 0" rpy="0 0 0" />
            <geometry>
                <mesh filename="package://meshes/L5/link4.STL" />
            </geometry>
        </collision>
    </link>
    <joint name="joint4" type="revolute">
        <origin xyz="0.245 0 -0.06" rpy="0 0 0" />
        <parent link="link3" />
        <child link="link4" />
        <axis xyz="0 1 0" />
        <limit lower="-10" upper="10" effort="100" velocity="1000" />
    </joint>
    <link name="link5">
        <inertial>
            <origin xyz="0.0036004 -1.5445E-05 0.055255" rpy="0 0 0" />
            <mass value="0.6353" />
            <inertia ixx="0.00254972"
                ixy="2.600e-7"
                ixz="-0.00021534"
                iyy="0.00255018"
                iyz="-5.980e-7"
                izz="0.00026961" />
        </inertial>
        <visual>
            <origin xyz="0 0 0" rpy="0 0 0" />
            <geometry>
                <mesh filename="package://meshes/L5/link5.STL" />
            </geometry>
            <material name="">
                <color rgba="0.69804 0.69804 0.69804 1" />
            </material>
        </visual>
        <collision>
            <origin xyz="0 0 0" rpy="0 0 0" />
            <geometry>
                <mesh filename="package://meshes/L5/link5.STL" />
            </geometry>
        </collision>
    </link>
    <joint name="joint5" type="revolute">
        <origin xyz="0.06775 -5E-05 -0.0865" rpy="0 0 0" />
        <parent link="link4" />
        <child link="link5" />
        <axis xyz="0 0 1" />
        <limit lower="-10" upper="10" effort="100" velocity="1000" />
    </joint>
    <link name="link6">
        <inertial>
            <origin xyz="0.050676 -4.9137E-05 5.123E-05" rpy="0 0 0" />
            <mass value="0.902" />
            <inertia ixx="0.00029" ixy="0.00000" ixz="0.00000" iyy="0.00028" iyz="-0.00001"
                izz="0.00045" />
        </inertial>
        <visual>
            <origin xyz="0 0 0" rpy="0 0 0" />
            <geometry>
                <mesh filename="package://meshes/L5/link6.STL" />
            </geometry>
            <material name="">
                <color rgba="0.79216 0.81961 0.93333 1" />
            </material>
        </visual>
        <collision>
            <origin xyz="0 0 0" rpy="0 0 0" />
            <geometry>
                <mesh filename="package://meshes/L5/link6.STL" />
            </geometry>
        </collision>
    </link>
    <joint name="joint6" type="revolute">
        <origin xyz="0.02895 0 0.0865" rpy="3.1416 0 0" />
        <parent link="link5" />
        <child link="link6" />
        <axis xyz="1 0 0" />
        <limit lower="-10" upper="10" effort="100" velocity="1000" />
    </joint>

    <link name="eef_link">
        <inertial>
            <mass value="0.0" />
            <origin xyz="0.0 0.0 0.0" rpy="0 0 0" />
            <inertia ixx="0.0" ixy="0.0" ixz="0.0" iyy="0.0" iyz="0.0" izz="0.0" />
        </inertial>
    </link>

    <joint name="gripper_fixed_joint" type="fixed">
        <origin xyz="0.235 0.0 0.0" rpy="0 0 0" />
        <parent link="link6" />
        <child link="eef_link" />
    </joint>
</robot>